<?xml version="1.0" encoding="utf-8"?>
<!-- This URDF was automatically created by SolidWorks to URDF Exporter! Originally created by Stephen Brawner (brawner@gmail.com) 
     Commit Version: 1.6.0-4-g7f85cfe  Build Version: 1.6.7995.38578
     For more information, please see http://wiki.ros.org/sw_urdf_exporter -->
<robot
  name="TARS_5Full">
  <link
    name="base_link">
    <inertial>
      <origin
        xyz="-0.01821 0.00046317 0.22021"
        rpy="0 0 0" />
      <mass
        value="95.139" />
      <inertia
        ixx="2.9406"
        ixy="-0.00026719"
        ixz="0.25102"
        iyy="5.1254"
        iyz="-0.00027604"
        izz="6.0329" />
    </inertial>
    <visual>
      <origin
        xyz="0 0 0"
        rpy="0 0 0" />
      <geometry>
        <mesh
          filename="package://TARS_5Full/meshes/base_link.STL" />
      </geometry>
      <material
        name="">
        <color
          rgba="0.75294 0.75294 0.75294 1" />
      </material>
    </visual>
    <collision>
      <origin
        xyz="0 0 0"
        rpy="0 0 0" />
      <geometry>
        <mesh
          filename="package://TARS_5Full/meshes/base_link.STL" />
      </geometry>
    </collision>
  </link>
  <link
    name="FL_Link">
    <inertial>
      <origin
        xyz="-2.7756E-17 -0.0275 0"
        rpy="0 0 0" />
      <mass
        value="1.8042" />
      <inertia
        ixx="0.0051847"
        ixy="2.4325E-21"
        ixz="-3.4653E-19"
        iyy="0.0094659"
        iyz="-1.8299E-18"
        izz="0.0051847" />
    </inertial>
    <visual>
      <origin
        xyz="0 0 0"
        rpy="0 0 0" />
      <geometry>
        <mesh
          filename="package://TARS_5Full/meshes/FL_Link.STL" />
      </geometry>
      <material
        name="">
        <color
          rgba="0.79216 0.81961 0.93333 1" />
      </material>
    </visual>
    <collision>
      <origin
        xyz="0 0 0"
        rpy="0 0 0" />
      <geometry>
        <mesh
          filename="package://TARS_5Full/meshes/FL_Link.STL" />
      </geometry>
    </collision>
  </link>
  <joint
    name="FL_Joint"
    type="continuous">
    <origin
      xyz="0.15 0.2475 0.0455"
      rpy="0 0 0" />
    <parent
      link="base_link" />
    <child
      link="FL_Link" />
    <axis
      xyz="0 -1 0" />
    <limit
      effort="0"
      velocity="1.5" />
  </joint>
  <link
    name="BL_Link">
    <inertial>
      <origin
        xyz="0 -0.0275 5.5511E-17"
        rpy="0 0 0" />
      <mass
        value="1.8042" />
      <inertia
        ixx="0.0051847"
        ixy="3.69E-19"
        ixz="-2.7977E-19"
        iyy="0.0094659"
        iyz="-3.1903E-18"
        izz="0.0051847" />
    </inertial>
    <visual>
      <origin
        xyz="0 0 0"
        rpy="0 0 0" />
      <geometry>
        <mesh
          filename="package://TARS_5Full/meshes/BL_Link.STL" />
      </geometry>
      <material
        name="">
        <color
          rgba="0.79216 0.81961 0.93333 1" />
      </material>
    </visual>
    <collision>
      <origin
        xyz="0 0 0"
        rpy="0 0 0" />
      <geometry>
        <mesh
          filename="package://TARS_5Full/meshes/BL_Link.STL" />
      </geometry>
    </collision>
  </link>
  <joint
    name="BL_Joint"
    type="continuous">
    <origin
      xyz="-0.15 0.2475 0.0455"
      rpy="0 0 0" />
    <parent
      link="base_link" />
    <child
      link="BL_Link" />
    <axis
      xyz="0 -1 0" />
    <limit
      effort="0"
      velocity="1.5" />
  </joint>
  <link
    name="BR_Link">
    <inertial>
      <origin
        xyz="0 0.0275 2.7756E-17"
        rpy="0 0 0" />
      <mass
        value="1.8042" />
      <inertia
        ixx="0.0051847"
        ixy="2.4335E-20"
        ixz="-7.549E-20"
        iyy="0.0094659"
        iyz="3.0863E-18"
        izz="0.0051847" />
    </inertial>
    <visual>
      <origin
        xyz="0 0 0"
        rpy="0 0 0" />
      <geometry>
        <mesh
          filename="package://TARS_5Full/meshes/BR_Link.STL" />
      </geometry>
      <material
        name="">
        <color
          rgba="0.79216 0.81961 0.93333 1" />
      </material>
    </visual>
    <collision>
      <origin
        xyz="0 0 0"
        rpy="0 0 0" />
      <geometry>
        <mesh
          filename="package://TARS_5Full/meshes/BR_Link.STL" />
      </geometry>
    </collision>
  </link>
  <joint
    name="BR_Joint"
    type="continuous">
    <origin
      xyz="-0.15 -0.2475 0.0455"
      rpy="0 0 0" />
    <parent
      link="base_link" />
    <child
      link="BR_Link" />
    <axis
      xyz="0 -1 0" />
    <limit
      effort="0"
      velocity="1.5" />
  </joint>
  <link
    name="FR_Link">
    <inertial>
      <origin
        xyz="-2.7756E-17 0.0275 2.7756E-17"
        rpy="0 0 0" />
      <mass
        value="1.8042" />
      <inertia
        ixx="0.0051847"
        ixy="-6.0209E-20"
        ixz="2.9347E-20"
        iyy="0.0094659"
        iyz="3.2384E-18"
        izz="0.0051847" />
    </inertial>
    <visual>
      <origin
        xyz="0 0 0"
        rpy="0 0 0" />
      <geometry>
        <mesh
          filename="package://TARS_5Full/meshes/FR_Link.STL" />
      </geometry>
      <material
        name="">
        <color
          rgba="0.79216 0.81961 0.93333 1" />
      </material>
    </visual>
    <collision>
      <origin
        xyz="0 0 0"
        rpy="0 0 0" />
      <geometry>
        <mesh
          filename="package://TARS_5Full/meshes/FR_Link.STL" />
      </geometry>
    </collision>
  </link>
  <joint
    name="FR_Joint"
    type="continuous">
    <origin
      xyz="0.15 -0.2475 0.0455"
      rpy="0 0 0" />
    <parent
      link="base_link" />
    <child
      link="FR_Link" />
    <axis
      xyz="0 -1 0" />
    <limit
      effort="0"
      velocity="1.5" />
  </joint>
  <link
    name="Lidar_Link">
    <inertial>
      <origin
        xyz="0.039987 -0.030612 -0.1868"
        rpy="0 0 0" />
      <mass
        value="2.3103" />
      <inertia
        ixx="0.0027513"
        ixy="2.2072E-19"
        ixz="-4.9174E-19"
        iyy="0.002027"
        iyz="-1.3752E-06"
        izz="0.0025637" />
    </inertial>
    <visual>
      <origin
        xyz="0 0 0"
        rpy="0 0 0" />
      <geometry>
        <mesh
          filename="package://TARS_5Full/meshes/Lidar_Link.STL" />
      </geometry>
      <material
        name="">
        <color
          rgba="0.75294 0.75294 0.75294 1" />
      </material>
    </visual>
    <collision>
      <origin
        xyz="0 0 0"
        rpy="0 0 0" />
      <geometry>
        <mesh
          filename="package://TARS_5Full/meshes/Lidar_Link.STL" />
      </geometry>
    </collision>
  </link>
  <joint
    name="Lidar_joint"
    type="fixed">
    <origin
      xyz="0.265 0 0.855"
      rpy="0 0 0" />
    <parent
      link="base_link" />
    <child
      link="Lidar_Link" />
    <axis
      xyz="0 0 0" />
  </joint>

<!--Skid Steer Plugin ..............................................-->

 <gazebo>
  <plugin name="skid_steer_drive_controller" filename="libgazebo_ros_skid_steer_drive.so">
    <updateRate>100.0</updateRate>
    <robotNamespace>/</robotNamespace>
    <leftFrontJoint>FL_Joint</leftFrontJoint>
    <rightFrontJoint>FR_Joint</rightFrontJoint>
    <leftRearJoint>BL_Joint</leftRearJoint>
    <rightRearJoint>BR_Joint</rightRearJoint>
    <wheelSeparation>0.495</wheelSeparation>
    <wheelDiameter>0.205</wheelDiameter>
    <robotBaseFrame>base_link</robotBaseFrame>
    <torque>20</torque>
    <commandTopic>cmd_vel</commandTopic>
    <odometryTopic>odom</odometryTopic>
    <odometryFrame>odom</odometryFrame>
    <broadcastTF>true</broadcastTF>
    <covariance_x>0.001</covariance_x> <!-- 0.0001 -->
    <covariance_y>0.001</covariance_y> <!-- 0.0001 -->
    <covariance_yaw>0.01</covariance_yaw> <!-- 0.01 -->
  </plugin>
</gazebo>

</robot>