<?xml version="1.0" encoding="utf-8"?>
<!-- This URDF was automatically created by SolidWorks to URDF Exporter! Originally created by Stephen Brawner (brawner@gmail.com) 
     Commit Version: 1.6.0-4-g7f85cfe  Build Version: 1.6.7995.38578
     For more information, please see http://wiki.ros.org/sw_urdf_exporter -->
<robot
  name="tars4">
  <link
    name="base_link">
    <inertial>
      <origin
        xyz="0.0732745727557489 0.000493510970256962 0.413214837428418"
        rpy="0 0 0" />
      <mass
        value="26.298368938694" />
      <inertia
        ixx="1.2118547835405"
        ixy="0.000301913650025786"
        ixz="0.244146054455403"
        iyy="2.63217845117372"
        iyz="-0.00186525892761391"
        izz="2.69232933962158" />
    </inertial>
    <visual>
      <origin
        xyz="0 0 0"
        rpy="0 0 0" />
      <geometry>
        <mesh
          filename="package://tars4/meshes/base_link.STL" />
      </geometry>
      <material
        name="white">
        <color
          rgba="1 1 1 1" />
      </material>
    </visual>
    <collision>
      <origin
        xyz="0 0 0"
        rpy="0 0 0" />
      <geometry>
        <mesh
          filename="package://tars4/meshes/base_link.STL" />
      </geometry>
    </collision>
  </link>
  <link
    name="frontleftwheel">
    <inertial>
      <origin
        xyz="-2.7756E-17 -0.0275 -8.3267E-17"
        rpy="0 0 0" />
      <mass
        value="1.8042" />
      <inertia
        ixx="0.0051847"
        ixy="6.6094E-20"
        ixz="-1.7149E-19"
        iyy="0.0094659"
        iyz="-1.8286E-18"
        izz="0.0051847" />
    </inertial>
    <visual>
      <origin
        xyz="0 0 0"
        rpy="0 0 0" />
      <geometry>
        <mesh
          filename="package://tars4/meshes/frontleftwheel.STL" />
      </geometry>
      <material
        name="">
        <color
          rgba="0 0 0 1" />
      </material>
    </visual>
    <collision>
      <origin
        xyz="0 0 0"
        rpy="0 0 0" />
      <geometry>
        <mesh
          filename="package://tars4/meshes/frontleftwheel.STL" />
      </geometry>
    </collision>
  </link>
  <gazebo reference="frontleftwheel">
    <material>Gazebo/Grey</material>
  </gazebo>


  <joint
    name="frontleftjoint"
    type="continuous">
    <origin
      xyz="0.14985 0.2475 0.05"
      rpy="0 0 0" />
    <parent
      link="base_link" />
    <child
      link="frontleftwheel" />
    <axis
      xyz="0 1 0" />
    <limit
      effort="1"
      velocity="1.5" />
  </joint>
  <link
    name="backleftwheel">
    <inertial>
      <origin
        xyz="-9.7145E-17 -0.0275 1.3878E-16"
        rpy="0 0 0" />
      <mass
        value="1.8042" />
      <inertia
        ixx="0.0051847"
        ixy="4.9875E-19"
        ixz="5.9653E-19"
        iyy="0.0094659"
        iyz="-3.044E-18"
        izz="0.0051847" />
    </inertial>
    <visual>
      <origin
        xyz="0 0 0"
        rpy="0 0 0" />
      <geometry>
        <mesh
          filename="package://tars4/meshes/backleftwheel.STL" />
      </geometry>
      <material
        name="">
        <color
          rgba="0 0 0 1" />
      </material>
    </visual>
    <collision>
      <origin
        xyz="0 0 0"
        rpy="0 0 0" />
      <geometry>
        <mesh
          filename="package://tars4/meshes/backleftwheel.STL" />
      </geometry>
    </collision>
  </link>

  <gazebo reference="backleftwheel">
    <material>Gazebo/Grey</material>
  </gazebo>
  <joint
    name="backleftjoint"
    type="continuous">
    <origin
      xyz="-0.15015 0.2475 0.05"
      rpy="0 0 0" />
    <parent
      link="base_link" />
    <child
      link="backleftwheel" />
    <axis
      xyz="0 1 0" />
    <limit
      effort="1"
      velocity="1.5" />
  </joint>
  <link
    name="frontrightwheel">
    <inertial>
      <origin
        xyz="0 0.0275 8.3267E-17"
        rpy="0 0 0" />
      <mass
        value="1.8042" />
      <inertia
        ixx="0.0051847"
        ixy="-1.216E-20"
        ixz="-6.3548E-19"
        iyy="0.0094659"
        iyz="3.4218E-18"
        izz="0.0051847" />
    </inertial>
    <visual>
      <origin
        xyz="0 0 0"
        rpy="0 0 0" />
      <geometry>
        <mesh
          filename="package://tars4/meshes/frontrightwheel.STL" />
      </geometry>
      <material
        name="">
        <color
          rgba="0 0 0 1" />
      </material>
    </visual>
    <collision>
      <origin
        xyz="0 0 0"
        rpy="0 0 0" />
      <geometry>
        <mesh
          filename="package://tars4/meshes/frontrightwheel.STL" />
      </geometry>
    </collision>
  </link>
  <gazebo reference="frontrightwheel">
    <material>Gazebo/Grey</material>
  </gazebo>
  <joint
    name="frontrightjoint"
    type="continuous">
    <origin
      xyz="0.14985 -0.2475 0.05"
      rpy="0 0 0" />
    <parent
      link="base_link" />
    <child
      link="frontrightwheel" />
    <axis
      xyz="0 1 0" />
    <limit
      effort="1"
      velocity="1.5" />
  </joint>
  <link
    name="backrightwheel">
    <inertial>
      <origin
        xyz="-9.7145E-17 0.0275 -1.3878E-16"
        rpy="0 0 0" />
      <mass
        value="1.8042" />
      <inertia
        ixx="0.0051847"
        ixy="9.3321E-20"
        ixz="2.4737E-19"
        iyy="0.0094659"
        iyz="3.0839E-18"
        izz="0.0051847" />
    </inertial>
    <visual>
      <origin
        xyz="0 0 0"
        rpy="0 0 0" />
      <geometry>
        <mesh
          filename="package://tars4/meshes/backrightwheel.STL" />
      </geometry>
      <material
        name="">
        <color
          rgba="0 0 0 1" />
      </material>
    </visual>
    <collision>
      <origin
        xyz="0 0 0"
        rpy="0 0 0" />
      <geometry>
        <mesh
          filename="package://tars4/meshes/backrightwheel.STL" />
      </geometry>
    </collision>
  </link>

<gazebo reference="backrightwheel">
    <material>Gazebo/Grey</material>
  </gazebo>

  <joint
    name="backrightjoint"
    type="continuous">
    <origin
      xyz="-0.15015 -0.2475 0.05"
      rpy="0 0 0" />
    <parent
      link="base_link" />
    <child
      link="backrightwheel" />
    <axis
      xyz="0 1 0" />
    <limit
      effort="1"
      velocity="1.5" />
  </joint>

  <joint name="camera_joint" type="fixed">
        <parent link="base_link"/>
        <child link="camera_link"/>
        <origin xyz="0.32636 0 0.65905" rpy="0 0 0"/>
    </joint>

    <link name="camera_link">
        <visual>
            <geometry>
                <box size="0.033 0.175 0.03"/>
                <material
                name="">
                <color
                rgba="0 0 0 1" />
               </material>
            </geometry>
        </visual>
    </link>


    <joint name="camera_optical_joint" type="fixed">
        <parent link="camera_link"/>
        <child link="camera_link_optical"/>
        <origin xyz="0 0 0" rpy="-1.57079632679 0 -1.57079632679"/>
    </joint>

    <link name="camera_link_optical"></link>



    <gazebo reference="camera_link">
        <material>Gazebo/Red</material>

        <sensor name="camera" type="depth">
            <pose> 0 0 0 0 0 0 </pose>
            <visualize>true</visualize>
            <update_rate>30</update_rate>
            <camera>
                <horizontal_fov>1.57079632679</horizontal_fov>
                <image>
                    <format>B8G8R8</format>
                    <width>1920</width>
                    <height>1080</height>
                </image>
                <clip>
                    <near>0.5</near>
                    <far>25.0</far>
                </clip>
            </camera>
            <plugin name="camera_controller" filename="libgazebo_ros_camera.so">
                <frame_name>camera_link_optical</frame_name>
                <cameraName>camera</cameraName>
                <min_depth>0.5</min_depth>
                <max_depth>25</max_depth>
            </plugin>
        </sensor>
    </gazebo>

<gazebo>
  <plugin name="skid_steer_drive_controller" filename="libgazebo_ros_skid_steer_drive.so">
    <updateRate>100.0</updateRate>
    <robotNamespace>/</robotNamespace>
    <leftFrontJoint>frontleftjoint</leftFrontJoint>
    <rightFrontJoint>frontrightjoint</rightFrontJoint>
    <leftRearJoint>backleftjoint</leftRearJoint>
    <rightRearJoint>backrightjoint</rightRearJoint>
    <wheelSeparation>0.495</wheelSeparation>
    <wheelDiameter>0.205</wheelDiameter>
    <robotBaseFrame>base_link</robotBaseFrame>
    <torque>20</torque>
    <commandTopic>cmd_vel</commandTopic>
    <odometryTopic>odom</odometryTopic>
    <odometryFrame>odom</odometryFrame>
    <broadcastTF>true</broadcastTF>
    <covariance_x>0.001</covariance_x> <!-- 0.0001 -->
    <covariance_y>0.001</covariance_y> <!-- 0.0001 -->
    <covariance_yaw>0.01</covariance_yaw> <!-- 0.01 -->
  </plugin>
</gazebo>

</robot>